Workbook

Sheet Dashboard
B2: 🏈 2026 NFL MOCK DRAFT ACCURACY DASHBOARD
B5: Colin's Model-Built Mock vs. 30 Professional Analyst Mocks | April 23, 2026
B7: 📊 YOUR MOCK DRAFT — KEY METRICS
B8: EXACT HITS (Player + Pick) | D8: TOP 10 HITS | F8: ROUND 1 HITS | H8: RIGHT PLAYER → RIGHT TEAM | J8: WITHIN 5 PICKS | L8: AVG PICK DIST
B9: ='Accuracy Analysis'!B38 -> 5 | D9: ='Accuracy Analysis'!D38 -> 8 | F9: ='Accuracy Analysis'!F38 -> 27 | H9: ='Accuracy Analysis'!H38 -> 5 | J9: ='Accuracy Analysis'!I38 -> 20 | L9: ='Accuracy Analysis'!K38 -> 3.2222222
B10: out of 32 picks | D10: correctly in actual top 10 | F10: players projected to R1 | H10: player-team combos nailed | J10: predictions within ±5 slots | L10: lower is better
B12: 🎯 YOUR RANKING
B13: EXACT HITS RANK | F13: R1 HIT RATE | I13: BEAT HOW MANY PROS?
B14: ="T-" & (RANK('Accuracy Analysis'!B38,'Accuracy Analysis'!B38:B70,0)) & " of 31" -> T-13 of 31 | F14: =TEXT('Accuracy Analysis'!G38,"0.0%") -> 84.4% | I14: =COUNTIF('Accuracy Analysis'!B39:B70,"<"&'Accuracy Analysis'!B38) & " of 30" -> 14 of 30
B16: 🏆 FULL LEADERBOARD (Sorted by Exact Hits)
B17: Rank | C17: Source | D17: Exact | E17: Exact % | F17: Top 10 | G17: Top 10 % | H17: R1 | I17: R1 % | J17: Team Match | K17: Within 5 | L17: Top 5 | M17: Avg Dist | N17: Unique
B18: =RANK(D18,D$18:D$50,0) -> 1 | C18: {=_xlfn.SORTBY(_xlfn._xlws.FILTER('Accuracy Analysis'!A38:L70,'Accuracy Analysis'!A38:A70<>""),_xlfn._xlws.FILTER('Accuracy Analysis'!B38:B70,'Accuracy Analysis'!A38:A70<>""),-1,_xlfn._xlws.FILTER('Accuracy Analysis'!D38:D70,'Accuracy Analysis'!A38:A70<>""),-1)} -> Lance Zierlein (NFL) | D18: 8 | E18: 0.25 | F18: 9 | G18: 0.9 | H18: 28 | I18: 0.875 | J18: 8 | K18: 22 | L18: 3 | M18: 3.0714286 | N18: 0
B19: =RANK(D19,D$18:D$50,0) -> 2 | C19: Dan Parr (NFL) | D19: 7 | E19: 0.21875 | F19: 9 | G19: 0.9 | H19: 28 | I19: 0.875 | J19: 7 | K19: 24 | L19: 4 | M19: 3 | N19: 2
B20: =RANK(D20,D$18:D$50,0) -> 2 | C20: Todd McShay (Ringer) | D20: 7 | E20: 0.21875 | F20: 8 | G20: 0.8 | H20: 28 | I20: 0.875 | J20: 7 | K20: 20 | L20: 4 | M20: 3.3571429 | N20: 3
B21: =RANK(D21,D$18:D$50,0) -> 2 | C21: Walt Cherepinsky (WalterFootball) | D21: 7 | E21: 0.21875 | F21: 8 | G21: 0.8 | H21: 24 | I21: 0.75 | J21: 7 | K21: 18 | L21: 4 | M21: 4.862069 | N21: 0
B22: =RANK(D22,D$18:D$50,0) -> 2 | C22: Tony Pauline (ES 4/22) | D22: 7 | E22: 0.21875 | F22: 8 | G22: 0.8 | H22: 24 | I22: 0.75 | J22: 7 | K22: 18 | L22: 4 | M22: 3.125 | N22: 1
B23: =RANK(D23,D$18:D$50,0) -> 2 | C23: Field Yates | D23: 7 | E23: 0.21875 | F23: 7 | G23: 0.7 | H23: 27 | I23: 0.84375 | J23: 7 | K23: 21 | L23: 4 | M23: 3.6296296 | N23: 1
B24: =RANK(D24,D$18:D$50,0) -> 7 | C24: Rob Rang (Fox) | D24: 6 | E24: 0.1875 | F24: 9 | G24: 0.9 | H24: 27 | I24: 0.84375 | J24: 6 | K24: 19 | L24: 4 | M24: 3.8888889 | N24: 0
B25: =RANK(D25,D$18:D$50,0) -> 7 | C25: Chad Reuter (NFL.com) | D25: 6 | E25: 0.1875 | F25: 9 | G25: 0.9 | H25: 27 | I25: 0.84375 | J25: 6 | K25: 18 | L25: 4 | M25: 4.6296296 | N25: 0
B26: =RANK(D26,D$18:D$50,0) -> 7 | C26: Josh Edwards (CBS) | D26: 6 | E26: 0.1875 | F26: 9 | G26: 0.9 | H26: 27 | I26: 0.84375 | J26: 6 | K26: 18 | L26: 4 | M26: 4.3703704 | N26: 2
B27: =RANK(D27,D$18:D$50,0) -> 7 | C27: Ryan Wilson (CBS) | D27: 6 | E27: 0.1875 | F27: 8 | G27: 0.8 | H27: 28 | I27: 0.875 | J27: 7 | K27: 18 | L27: 4 | M27: 4.5357143 | N27: 0
B28: =RANK(D28,D$18:D$50,0) -> 7 | C28: Jason Boris (Times News) | D28: 6 | E28: 0.1875 | F28: 7 | G28: 0.7 | H28: 29 | I28: 0.90625 | J28: 6 | K28: 17 | L28: 4 | M28: 4.7407407 | N28: 0
B29: =RANK(D29,D$18:D$50,0) -> 7 | C29: Ryan McCrystal (Sharp) | D29: 6 | E29: 0.1875 | F29: 7 | G29: 0.7 | H29: 29 | I29: 0.90625 | J29: 6 | K29: 16 | L29: 3 | M29: 4.7586207 | N29: 0
B30: =RANK(D30,D$18:D$50,0) -> 13 | C30: Peter Schrager | D30: 5 | E30: 0.15625 | F30: 9 | G30: 0.9 | H30: 28 | I30: 0.875 | J30: 5 | K30: 22 | L30: 4 | M30: 3.5357143 | N30: 0
... B50: =RANK(D50,D$18:D$50,0) -> 33 | C50: Brent Sobleski (B/R 4/21) | D50: 0 | E50: 0 | F50: 2 | G50: 0.2 | H50: 17 | I50: 0.53125 | J50: 1 | K50: 4 | L50: 1 | M50: 10.235294 | N50: 0
B52: 💡 KEY INSIGHTS
B53: 🥇 TOP ANALYST | E53: 📊 AVG EXACT HITS | H53: 🎯 BEST R1 COVERAGE | K53: 🏈 YOUR PERCENTILE
B54: =INDEX('Accuracy Analysis'!A38:A70,MATCH(MAX('Accuracy Analysis'!B38:B70),'Accuracy Analysis'!B38:B70,0)) & " (" & MAX('Accuracy Analysis'!B38:B70) & " exact)" -> Lance Zierlein (NFL) (8 exact) | E54: =TEXT(AVERAGE('Accuracy Analysis'!B38:B70),"0.0") & " of 32 across " & COUNTA('Accuracy Analysis'!A38:A70) & " mocks" -> 4.5 of 32 across 33 mocks | H54: =INDEX('Accuracy Analysis'!A38:A70,MATCH(MAX('Accuracy Analysis'!F38:F70),'Accuracy Analysis'!F38:F70,0)) & " (" & MAX('Accuracy Analysis'!F38:F70) & "/32)" -> Luke Easterling (Athlon) (30/32) | K54: =TEXT(COUNTIF('Accuracy Analysis'!B39:B70,"<="&'Accuracy Analysis'!B38)/COUNTA('Accuracy Analysis'!A39:A70),"0%") & " — Beat " & COUNTIF('Accuracy Analysis'!B39:B70,"<"&'Accuracy Analysis'!B38) & " analysts" -> 63% — Beat 14 analysts
B56: 📌 Data sources: Accuracy Analysis sheet (rows 38-70). All values are live formula-linked — update automatically when source data changes.

Sheet Colin's Mock
A1: pick | B1: round | C1: team | D1: player | E1: position | F1: college | G1: rank
A2: 1 | B2: 1 | C2: LV | D2: Fernando Mendoza | E2: QB | F2: Indiana | G2: 1
A3: 2 | B3: 1 | C3: NYJ | D3: David Bailey | E3: EDGE | F3: Texas Tech | G3: 5
A4: 3 | B4: 1 | C4: ARI | D4: Arvell Reese | E4: LB | F4: Ohio State | G4: 3
A5: 4 | B5: 1 | C5: TEN | D5: Jeremiyah Love | E5: RB | F5: Notre Dame | G5: 2
A6: 5 | B6: 1 | C6: NYG | D6: Sonny Styles | E6: LB | F6: Ohio State | G6: 4
A7: 6 | B7: 1 | C7: CLE | D7: Francis Mauigoa | E7: OT | F7: Miami (FL) | G7: 9
A8: 7 | B8: 1 | C8: WAS | D8: Carnell Tate | E8: WR | F8: Ohio State | G8: 8
A9: 8 | B9: 1 | C9: NO | D9: Rueben Bain | E9: EDGE | F9: Miami (FL) | G9: 16
A10: 9 | B10: 1 | C10: KC | D10: Mansoor Delane | E10: CB | F10: LSU | G10: 14
A11: 10 | B11: 1 | C11: NYG | D11: Caleb Downs | E11: S | F11: Ohio State | G11: 6
A12: 11 | B12: 1 | C12: MIA | D12: Jordyn Tyson | E12: WR | F12: Arizona State | G12: 7
A13: 12 | B13: 1 | C13: DAL | D13: Spencer Fano | E13: OT | F13: Utah | G13: 10
... A258: 257 | B258: 7 | C258: DEN | D258: Micah Morris | E258: IOL | F258: Georgia | G258: 269

Sheet Actual nfl first round
A1: Round | B1: Pick | C1: Team | D1: Player (College, Pos) | E1: Trade From
A2: 1 | B2: 1 | C2: Raiders | D2: Fernando MendozaIndiana, QB · POS RK 1 | E2: -
A3: 1 | B3: 2 | C3: Jets | D3: David BaileyTexas Tech, LB · POS RK 2 | E3: -
A4: 1 | B4: 3 | C4: Cardinals | D4: Jeremiyah LoveNotre Dame, RB · POS RK 1 | E4: -
A5: 1 | B5: 4 | C5: Titans | D5: Carnell TateOhio State, WR · POS RK 1 | E5: -
A6: 1 | B6: 5 | C6: Giants | D6: Arvell ReeseOhio State, LB · POS RK 1 | E6: -
A7: 1 | B7: 6 | C7: Chiefs | D7: Mansoor DelaneLSU, CB · POS RK 1 | E7: CLE
A8: 1 | B8: 7 | C8: Commanders | D8: Sonny StylesOhio State, LB · POS RK 3 | E8: -
A9: 1 | B9: 8 | C9: Saints | D9: Jordyn TysonArizona State, WR · POS RK 3 | E9: -
A10: 1 | B10: 9 | C10: Browns | D10: Spencer FanoUtah, T · POS RK 2 | E10: KC
A11: 1 | B11: 10 | C11: Giants | D11: Francis MauigoaMiami (FL), T · POS RK 1 | E11: CIN
A12: 1 | B12: 11 | C12: Cowboys | D12: Caleb DownsOhio State, S · POS RK 1 | E12: MIA
A13: 1 | B13: 12 | C13: Dolphins | D13: Kadyn ProctorAlabama, T · POS RK 4 | E13: DAL
... A32: 1 | B32: 31 | C32: Titans | D32: Keldric FaulkAuburn, DE · POS RK 2 | E32: NE, BUF
A33: 1 | B33: 32 | C33: Seahawks | D33: Jadarian PriceNotre Dame, RB · POS RK 2

Sheet Other analyst 
A1: Pick # | B1: Team | C1: Field Yates | D1: Mel Kiper Jr. | E1: Peter Schrager | F1: Matt Miller | G1: Jordan Reid | H1: Daniel Jeremiah | I1: Ryan Wilson (CBS) | J1: Brendan Donahue | K1: Dan Parr (NFL.com) | L1: Yahoo (Tice/McDonald) | M1: Rob Rang (Fox) | N1: Lance Zierlein (NFL.com) | O1: Bucky Brooks (NFL final 4/21) | P1: Eric Edholm (NFL.com) | Q1: Pete Prisco (CBS) | R1: Todd McShay (Ringer) | S1: NFL Nation (ESPN 4/21) | T1: Rob Paul (SBR 3.0 4/23) | U1: Lance Reddick/PFF ADP (4/23) | V1: Brent Sobleski (B/R 4/21 Scouting) | W1: Lou Pickney (DKDB 4/23) | X1: Walt Cherepinsky (WalterFootball 4/23) | Y1: Charlie Campbell (WalterFootball 4/23) | Z1: Chad Reuter (NFL.com 4/20) | AA1: Jason Boris (Times News 4/23) | AB1: Luke Easterling (Athlon 4/23) | AC1: Vinnie Iyer (Sporting News 4/23) | AD1: Tony Pauline (ES 4/22) | AE1: Charles Davis (NFL.com) | AF1: Josh Edwards (CBS 4/16) | AG1: Ryan McCrystal (Sharp 4/23)
A2: 1 | B2: Las Vegas Raiders | C2: Fernando Mendoza (QB, Indiana) | D2: Fernando Mendoza (QB, Indiana) | E2: Fernando Mendoza (QB, Indiana) | F2: Fernando Mendoza (QB, Indiana) | G2: Fernando Mendoza (QB, Indiana) | H2: Fernando Mendoza (QB, Indiana) | I2: Fernando Mendoza (QB, Indiana) | J2: Fernando Mendoza (QB, Indiana) | K2: Fernando Mendoza (QB, Indiana) | L2: Fernando Mendoza (QB, Indiana) | M2: Fernando Mendoza (QB, Indiana) | N2: Fernando Mendoza (QB, Indiana) | O2: Fernando Mendoza (QB, Indiana) | P2: Fernando Mendoza (QB, Indiana) | Q2: Fernando Mendoza (QB, Indiana) | R2: Fernando Mendoza (QB, Indiana) | S2: Fernando Mendoza | T2: Fernando Mendoza | U2: Fernando Mendoza | V2: Arch Manning | W2: Fernando Mendoza | X2: Fernando Mendoza | Y2: Fernando Mendoza | Z2: Fernando Mendoza | AA2: Fernando Mendoza | AB2: Fernando Mendoza | AC2: Fernando Mendoza | AD2: Fernando Mendoza | AE2: Fernando Mendoza | AF2: Fernando Mendoza | AG2: Fernando Mendoza
A3: 2 | B3: New York Jets | C3: David Bailey (EDGE, Texas Tech) | D3: David Bailey (EDGE, Texas Tech) | E3: David Bailey (EDGE, Texas Tech) | F3: David Bailey (EDGE, Texas Tech) | G3: Arvell Reese (LB/EDGE, Ohio State) | H3: David Bailey (EDGE, Texas Tech) | I3: David Bailey (EDGE, Texas Tech) | J3: Arvell Reese (EDGE, Ohio State) | K3: Arvell Reese (LB/EDGE, Ohio State) | L3: David Bailey (EDGE, Texas Tech) | M3: David Bailey (EDGE, Texas Tech) | N3: David Bailey (EDGE, Texas Tech) | O3: David Bailey (EDGE, Texas Tech) | P3: Arvell Reese (LB/EDGE, Ohio State) | Q3: David Bailey (EDGE, Texas Tech) | R3: David Bailey (EDGE, Texas Tech) | S3: David Bailey | T3: Arvell Reese | U3: Arvell Reese | V3: Fernando Mendoza | W3: David Bailey | X3: David Bailey | Y3: David Bailey | Z3: Arvell Reese | AA3: David Bailey | AB3: David Bailey | AC3: Arvell Reese | AD3: David Bailey | AE3: Arvell Reese | AF3: David Bailey | AG3: David Bailey
A4: 3 | B4: Arizona Cardinals | C4: Jeremiyah Love (RB, Notre Dame) | D4: Arvell Reese (EDGE, Ohio State) | E4: Jeremiyah Love (RB, Notre Dame) | F4: Arvell Reese (EDGE, Ohio State) | G4: Francis Mauigoa (OT, Miami) | H4: [→ New Orleans Saints (trade)] Arvell Reese (LB/EDGE, Ohio State) | I4: Arvell Reese (EDGE, Ohio State) | J4: David Bailey (EDGE, Texas Tech) | K4: Jeremiyah Love (RB, Notre Dame) | L4: [→ KC trade] Arvell Reese (EDGE, Ohio State) | M4: Jeremiyah Love (RB, Notre Dame) | N4: Jeremiyah Love (RB, Notre Dame) | O4: Arvell Reese (EDGE, Ohio State) | P4: David Bailey (EDGE, Texas Tech) | Q4: Jeremiyah Love (RB, Notre Dame) | R4: Arvell Reese (EDGE, Ohio State) | S4: Arvell Reese | T4: David Bailey | U4: Jeremiyah Love | V4: Dante Moore | W4: Francis Mauigoa | X4: Jeremiyah Love | Y4: Jeremiyah Love | Z4: David Bailey | AA4: Jeremiyah Love | AB4: Jeremiyah Love | AC4: David Bailey | AD4: Jeremiyah Love | AE4: Ty Simpson | AF4: Francis Mauigoa | AG4: Jeremiyah Love
A5: 4 | B5: Tennessee Titans | C5: Sonny Styles (LB, Ohio State) | D5: Jeremiyah Love (RB, Notre Dame) | E5: Sonny Styles (LB, Ohio State) | F5: Jeremiyah Love (RB, Notre Dame) | G5: David Bailey (EDGE, Texas Tech) | H5: Sonny Styles (LB, Ohio State) | I5: Jeremiyah Love (RB, Notre Dame) | J5: Jeremiyah Love (RB, Notre Dame) | K5: David Bailey (EDGE, Texas Tech) | L5: Sonny Styles (LB, Ohio State) | M5: Arvell Reese (LB, Ohio State) | N5: Sonny Styles (LB, Ohio State) | O5: Jeremiyah Love (RB, Notre Dame) | P5: Jeremiyah Love (RB, Notre Dame) | Q5: Arvell Reese (EDGE, Ohio State) | R5: Sonny Styles (LB, Ohio State) | S5: Sonny Styles | T5: Jeremiyah Love | U5: David Bailey | V5: Jeremiah Smith | W5: Arvell Reese | X5: Arvell Reese | Y5: Sonny Styles | Z5: Jeremiyah Love | AA5: Arvell Reese | AB5: Sonny Styles | AC5: Jeremiyah Love | AD5: Sonny Styles | AE5: David Bailey | AF5: Arvell Reese | AG5: Sonny Styles
A6: 5 | B6: New York Giants | C6: Arvell Reese (EDGE, Ohio State) | D6: Caleb Downs (S, Ohio State) | E6: Arvell Reese (EDGE, Ohio State) | F6: Jordyn Tyson (WR, Arizona State) | G6: Sonny Styles (LB, Ohio State) | H6: Jeremiyah Love (RB, Notre Dame) | I6: Caleb Downs (S, Ohio State) | J6: Sonny Styles (LB, Ohio State) | K6: Jordyn Tyson (WR, Arizona State) | L6: Caleb Downs (S, Ohio State) | M6: Caleb Downs (S, Ohio State) | N6: Caleb Downs (S, Ohio State) | O6: Jordyn Tyson (WR, Arizona State) | P6: Sonny Styles (LB, Ohio State) | Q6: Sonny Styles (LB, Ohio State) | R6: Jeremiyah Love (RB, Notre Dame) | S6: Jeremiyah Love | T6: Caleb Downs | U6: Sonny Styles | V6: Cam Coleman | W6: Sonny Styles | X6: Jordyn Tyson | Y6: Jordyn Tyson | Z6: Francis Mauigoa | AA6: Jordyn Tyson | AB6: Jordyn Tyson | AC6: Sonny Styles | AD6: Arvell Reese | AE6: Jeremiyah Love | AF6: Carnell Tate | AG6: Caleb Downs
A7: 6 | B7: Cleveland Browns | C7: Monroe Freeling (OT, Georgia) | D7: [→ Dallas Cowboys (trade)] Sonny Styles (LB, Ohio State) | E7: Spencer Fano (OT, Utah) | F7: Francis Mauigoa (OT, Miami) | G7: Carnell Tate (WR, Ohio State) | H7: Spencer Fano (OT, Utah) | I7: [→ Dallas Cowboys (trade)] Sonny Styles (LB, Ohio State) | J7: Carnell Tate (WR, Ohio State) | K7: Spencer Fano (OT, Utah) | L7: Carnell Tate (WR, Ohio State) | M7: Spencer Fano (OT, Utah) | N7: [→ DAL trade] Arvell Reese (LB/EDGE, Ohio State) | O7: Carnell Tate (WR, Ohio State) | P7: Carnell Tate (WR, Ohio State) | Q7: Kadyn Proctor (OT, Alabama) | R7: Kadyn Proctor (OT, Alabama) | S7: Francis Mauigoa | T7: Sonny Styles | U7: Francis Mauigoa | V7: Jayden Maiava | W7: Carnell Tate | X7: Spencer Fano | Y7: Francis Mauigoa | Z7: Monroe Freeling | AA7: Spencer Fano | AB7: Arvell Reese | AC7: Carnell Tate | AD7: Rueben Bain Jr. | AE7: Carnell Tate | AF7: Sonny Styles | AG7: Spencer Fano
A8: 7 | B8: Washington Commanders | C8: Carnell Tate (WR, Ohio State) | D8: Carnell Tate (WR, Ohio State) | E8: Carnell Tate (WR, Ohio State) | F8: Sonny Styles (LB, Ohio State) | G8: Jeremiyah Love (RB, Notre Dame) | H8: Jordyn Tyson (WR, Arizona State) | I8: Carnell Tate (WR, Ohio State) | J8: Mansoor Delane (CB, LSU) | K8: Sonny Styles (LB, Ohio State) | L8: Jeremiyah Love (RB, Notre Dame) | M8: Sonny Styles (LB, Ohio State) | N8: Carnell Tate (WR, Ohio State) | O8: Sonny Styles (LB, Ohio State) | P8: Mansoor Delane (CB, LSU) | Q8: Jordyn Tyson (WR, Arizona State) | R8: Mansoor Delane (CB, LSU) | S8: Mansoor Delane | T8: Francis Mauigoa | U8: Carnell Tate | V8: Dylan Stewart | W8: Jeremiyah Love | X8: Carnell Tate | Y8: Carnell Tate | Z8: Mansoor Delane | AA8: Sonny Styles | AB8: Carnell Tate | AC8: Caleb Downs | AD8: Caleb Downs | AE8: Sonny Styles | AF8: Jeremiyah Love | AG8: Mansoor Delane
A9: 8 | B9: New Orleans Saints | C9: Jordyn Tyson (WR, Arizona State) | D9: Rueben Bain Jr. (EDGE, Miami) | E9: Caleb Downs (S, Ohio State) | F9: Carnell Tate (WR, Ohio State) | G9: Mansoor Delane (CB, LSU) | H9: [→ Arizona Cardinals (trade)] Francis Mauigoa (OT, Miami) | I9: Rueben Bain Jr. (EDGE, Miami) | J9: Rueben Bain Jr. (EDGE, Miami) | K9: Carnell Tate (WR, Ohio State) | L9: Rueben Bain Jr. (EDGE, Miami) | M9: Carnell Tate (WR, Ohio State) | N9: Jordyn Tyson (WR, Arizona State) | O9: Rueben Bain Jr. (EDGE, Miami) | P9: Jordyn Tyson (WR, Arizona State) | Q9: Carnell Tate (WR, Ohio State) | R9: Rueben Bain Jr. (EDGE, Miami) | S9: Carnell Tate | T9: Carnell Tate | U9: Rueben Bain Jr. | V9: Colin Simmons | W9: Makai Lemon | X9: Caleb Downs | Y9: Arvell Reese | Z9: Rueben Bain Jr. | AA9: Caleb Downs | AB9: Mansoor Delane | AC9: Rueben Bain Jr. | AD9: Mansoor Delane | AE9: Jordyn Tyson | AF9: Mansoor Delane | AG9: Jordyn Tyson
A10: 9 | B10: Kansas City Chiefs | C10: Caleb Downs (S, Ohio State) | D10: Jordyn Tyson (WR, Arizona State) | E10: [→ Dallas Cowboys (trade)] Mansoor Delane (CB, LSU) | F10: Rueben Bain Jr. (EDGE, Miami) | G10: Rueben Bain Jr. (EDGE, Miami) | H10: Mansoor Delane (CB, LSU) | I10: Jordyn Tyson (WR, Arizona State) | J10: [→ Dallas Cowboys (trade)] Caleb Downs (S, Ohio State) | K10: Mansoor Delane (CB, LSU) | L10: [→ ARI trade] Francis Mauigoa (OT, Miami) | M10: Mansoor Delane (CB, LSU) | N10: Mansoor Delane (CB, LSU) | O10: Kenyon Sadiq (TE, Oregon) | P10: Francis Mauigoa (OT, Miami) | Q10: Rueben Bain Jr. (EDGE, Miami) | R10: Jordyn Tyson (WR, Arizona State) | S10: Rueben Bain Jr. | T10: Rueben Bain Jr. | U10: Caleb Downs | V10: Leonard Moore | W10: Mansoor Delane | X10: Rueben Bain Jr. | Y10: Rueben Bain Jr. | Z10: Kadyn Proctor | AA10: Rueben Bain Jr. | AB10: Rueben Bain Jr. | AC10: Mansoor Delane | AD10: Spencer Fano | AE10: Rueben Bain Jr. | AF10: Spencer Fano | AG10: Rueben Bain Jr.
A11: 10 | B11: New York Giants (via CIN) | C11: Olaivavega Ioane (G, Penn State) | D11: Francis Mauigoa (OT, Miami) | E11: Jordyn Tyson (WR, Arizona State) | F11: Caleb Downs (S, Ohio State) | G11: Caleb Downs (S, Ohio State) | H11: Carnell Tate (WR, Ohio State) | I11: Francis Mauigoa (OT, Miami) | J11: Jermod McCoy (CB, Tennessee) | K11: Caleb Downs (S, Ohio State) | L11: Keldric Faulk (EDGE, Auburn) | M11: Francis Mauigoa (OL, Miami) | N11: Francis Mauigoa (OL, Miami) | O11: Caleb Downs (S, Ohio State) | P11: Caleb Downs (S, Ohio State) | Q11: Caleb Downs (S, Ohio State) | R11: Francis Mauigoa (OT, Miami) | S11: Caleb Downs | T11: Olaivavega Ioane | U11: Mansoor Delane | V11: Arvell Reese | W11: Caleb Downs | X11: Mansoor Delane | Y11: Mansoor Delane | Z11: Caleb Downs | AA11: Francis Mauigoa | AB11: Caleb Downs | AC11: Jordyn Tyson | AD11: Carnell Tate | AE11: Caleb Downs | AF11: Rueben Bain Jr. | AG11: Olaivavega Ioane
A12: 11 | B12: Miami Dolphins | C12: Francis Mauigoa (OT, Miami) | D12: Mansoor Delane (CB, LSU) | E12: Francis Mauigoa (OT, Miami) | F12: Spencer Fano (OT, Utah) | G12: Spencer Fano (OT, Utah) | H12: Rueben Bain Jr. (EDGE, Miami) | I12: Mansoor Delane (CB, LSU) | J12: Spencer Fano (OT, Utah) | K12: Francis Mauigoa (OT, Miami) | L12: Mansoor Delane (CB, LSU) | M12: Jordyn Tyson (WR, Arizona State) | N12: Rueben Bain Jr. (EDGE, Miami) | O12: Mansoor Delane (CB, LSU) | P12: Rueben Bain Jr. (EDGE, Miami) | Q12: Spencer Fano (OT, Utah) | R12: Spencer Fano (OT, Utah) | S12: Spencer Fano | T12: Mansoor Delane | U12: Makai Lemon | V12: Malachi Toney | W12: Jermod McCoy | X12: Kadyn Proctor | Y12: Kadyn Proctor | Z12: Carnell Tate | AA12: Kadyn Proctor | AB12: Francis Mauigoa | AC12: Spencer Fano | AD12: Francis Mauigoa | AE12: Kenyon Sadiq | AF12: Caleb Downs | AG12: Francis Mauigoa
A13: 12 | B13: Dallas Cowboys | C13: Mansoor Delane (CB, LSU) | D13: [→ Cleveland Browns (trade)] Kadyn Proctor (OT, Alabama) | E13: [→ Kansas City Chiefs (trade)] Rueben Bain Jr. (EDGE, Miami) | F13: Mansoor Delane (CB, LSU) | G13: Dillon Thieneman (S, Oregon) | H13: Caleb Downs (S, Ohio State) | I13: [→ Cleveland Browns (trade)] Spencer Fano (OT, Utah) | J13: [→ Kansas City Chiefs (trade)] Jordyn Tyson (WR, Arizona State) | K13: Rueben Bain Jr. (EDGE, Miami) | L13: Jermod McCoy (CB, Tennessee) | M13: Rueben Bain Jr. (EDGE, Miami) | N13: [→ CLE trade] Spencer Fano (OL, Utah) | O13: Dillon Thieneman (S, Oregon) | P13: Keldric Faulk (EDGE, Auburn) | Q13: Mansoor Delane (CB, LSU) | R13: Caleb Downs (S, Ohio State) | S13: Jordyn Tyson | T13: Spencer Fano | U13: Spencer Fano | V13: Sonny Styles | W13: Rueben Bain Jr. | X13: Sonny Styles | Y13: Caleb Downs | Z13: Sonny Styles | AA13: Mansoor Delane | AB13: Spencer Fano | AC13: Jermod McCoy | AD13: Jordyn Tyson | AE13: Mansoor Delane | AF13: Monroe Freeling | AG13: Arvell Reese
... A33: 32 | B33: Seattle Seahawks | C33: T.J. Parker (EDGE, Clemson) | D33: Jadarian Price (RB, Notre Dame) | E33: [→ Arizona Cardinals (trade)] Ty Simpson (QB, Alabama) | F33: Malachi Lawrence (EDGE, UCF) | G33: Chase Bisontis (G, Texas A&M) | H33: [→ Baltimore Ravens (trade)] Peter Woods (DL, Clemson) | I33: Jadarian Price (RB, Notre Dame) | J33: T.J. Parker (EDGE, Clemson) | K33: Chris Johnson (CB, San Diego State) | L33: Avieon Terrell (CB, Clemson) | M33: Jadarian Price (RB, Notre Dame) | N33: Jadarian Price (RB, Notre Dame) | O33: Malachi Lawrence (EDGE, UCF) | P33: Chris Johnson (CB, San Diego State) | Q33: Jadarian Price (RB, Notre Dame) | R33: Chris Johnson (CB, San Diego State) | S33: Chris Johnson | T33: Colton Hood | U33: KC Concepcion | V33: Ahmad Hardy | W33: Colton Hood | X33: Ty Simpson | Y33: Jadarian Price | Z33: R Mason Thomas | AA33: Ty Simpson | AB33: Jadarian Price | AC33: C.J. Allen | AD33: Keldric Faulk | AE33: Avieon Terrell | AF33: Jadarian Price | AG33: Ty Simpson

Sheet Accuracy Analysis
A1: Pick # | B1: Actual Team | C1: Actual Player | D1: Colin's Mock | E1: Field Yates | F1: Mel Kiper Jr. | G1: Peter Schrager | H1: Matt Miller | I1: Jordan Reid | K1: Colin Exact | L1: Yates Exact | M1: Kiper Exact | N1: Schrager Exact | O1: Miller Exact | P1: Reid Exact | Q1: Colin in R1 | R1: Yates in R1 | S1: Kiper in R1 | T1: Schrager in R1 | U1: Miller in R1 | V1: Reid in R1 | W1: Colin Team Match | X1: Yates Team Match | Y1: Kiper Team Match | Z1: Schrager Team Match | AA1: Miller Team Match | AB1: Reid Team Match | AC1: Daniel Jeremiah | AD1: Ryan Wilson (CBS) | AE1: Brendan Donahue | AF1: Jeremiah Exact | AG1: Jeremiah in R1 | AH1: Jeremiah Team Match | AI1: Wilson Exact | AJ1: Wilson in R1 | AK1: Wilson Team Match | AL1: Donahue Exact | AM1: Donahue in R1 | AN1: Donahue Team Match | AO1: Dan Parr | AP1: Dan Exact | AQ1: Dan in R1 | AR1: Dan Team Match | AS1: Yahoo (Tice/McDonald) | AT1: Yahoo Exact | AU1: Yahoo in R1 | AV1: Yahoo Team Match | AW1: Rob Rang | AX1: Rob Exact | AY1: Rob in R1 | AZ1: Rob Team Match | BA1: Lance Zierlein | BB1: Lance Exact | BC1: Lance in R1 | BD1: Lance Team Match | BE1: Bucky Brooks | BF1: Bucky Exact | BG1: Bucky in R1 | BH1: Bucky Team Match | BI1: Eric Edholm | BJ1: Eric Exact | BK1: Eric in R1 | BL1: Eric Team Match | BM1: Pete Prisco | BN1: Pete Exact | BO1: Pete in R1 | BP1: Pete Team Match | BQ1: Todd McShay | BR1: Todd Exact | BS1: Todd in R1 | BT1: Todd Team Match | BU1: Colin w/Trade | BV1: ColinTrade Exact | BW1: ColinTrade in R1 | BX1: ColinTrade Team Match | CA1: LV | CB1: Raiders | CC1: NFL Nation (ESPN 4/21) | CD1: NFLNation Exact | CE1: NFLNation in R1 | CF1: NFLNation Team Match | CG1: Rob Paul (SBR 4/23) | CH1: RobPaul Exact | CI1: RobPaul in R1 | CJ1: RobPaul Team Match | CK1: PFF ADP (4/23) | CL1: PFF Exact | CM1: PFF in R1 | CN1: PFF Team Match | CO1: Brent Sobleski (B/R 4/21) | CP1: Brent Exact | CQ1: Brent in R1 | CR1: Brent Team Match | CS1: Lou Pickney (DKDB 4/13) | CT1: Lou Exact | CU1: Lou in R1 | CV1: Lou Team Match | CW1: Tony Pauline | CX1: Pauline Exact | CY1: Pauline in R1 | CZ1: Pauline Team Match | DA1: Charles Davis | DB1: Davis Exact | DC1: Davis in R1 | DD1: Davis Team Match | DE1: Josh Edwards | DF1: Edwards Exact | DG1: Edwards in R1 | DH1: Edwards Team Match | DI1: Ryan McCrystal | DJ1: McCrystal Exact | DK1: McCrystal in R1 | DL1: McCrystal Team Match | DM1: Luke Easterling (Athlon 4/23) | DN1: Easter Exact | DO1: Easter in R1 | DP1: Easter Team Match | DQ1: Vinnie Iyer (SN 4/23) | DR1: Iyer Exact | DS1: Iyer in R1 | DT1: Iyer Team Match | DU1: Walt Cherepinsky | DV1: Walt Exact | DW1: Walt in R1 | DX1: Walt Team Match | DY1: Charlie Campbell | DZ1: Charlie Exact | EA1: Charlie in R1 | EB1: Charlie Team Match | EC1: Chad Reuter | ED1: Chad Exact | EE1: Chad in R1 | EF1: Chad Team Match | EG1: Jason Boris | EH1: Jason Exact | EI1: Jason in R1 | EJ1: Jason Team Match | EK1: Total Exact Hits (all analysts)
A2: 1 | B2: ='Actual nfl first round'!C2 -> Raiders | C2: {=_xlfn.LET(_xlpm.actual, 'Actual nfl first round'!D2, _xlpm.analystNames, _xlfn.TOCOL($E$2:$I$33), _xlpm.mockNames, 'Colin''s Mock'!$D$2:$D$258, _xlpm.allNames, _xlfn.VSTACK(_xlpm.analystNames, _xlpm.mockNames), _xlpm.matches, _xlfn._xlws.FILTER(_xlpm.allNames, ISNUMBER(SEARCH(_xlpm.allNames, _xlpm.actual))*(LEN(_xlpm.allNames)>3), ""), IF(ISERROR(INDEX(_xlpm.matches,1)), _xlpm.actual, INDEX(_xlpm.matches,1)))} -> Fernando Mendoza | D2: ='Colin''s Mock'!D2 -> Fernando Mendoza | E2: =_xlfn.LET(_xlpm.raw, 'Other analyst '!C2, _xlpm.s, IF(LEFT(_xlpm.raw,1)="[", MID(_xlpm.raw, FIND("] ",_xlpm.raw)+2, 999), _xlpm.raw), IFERROR(TRIM(LEFT(_xlpm.s, FIND(" (",_xlpm.s)-1)), _xlpm.raw)) -> Fernando Mendoza | F2: =_xlfn.LET(_xlpm.raw, 'Other analyst '!D2, _xlpm.s, IF(LEFT(_xlpm.raw,1)="[", MID(_xlpm.raw, FIND("] ",_xlpm.raw)+2, 999), _xlpm.raw), IFERROR(TRIM(LEFT(_xlpm.s, FIND(" (",_xlpm.s)-1)), _xlpm.raw)) -> Fernando Mendoza | G2: =_xlfn.LET(_xlpm.raw, 'Other analyst '!E2, _xlpm.s, IF(LEFT(_xlpm.raw,1)="[", MID(_xlpm.raw, FIND("] ",_xlpm.raw)+2, 999), _xlpm.raw), IFERROR(TRIM(LEFT(_xlpm.s, FIND(" (",_xlpm.s)-1)), _xlpm.raw)) -> Fernando Mendoza | H2: =_xlfn.LET(_xlpm.raw, 'Other analyst '!F2, _xlpm.s, IF(LEFT(_xlpm.raw,1)="[", MID(_xlpm.raw, FIND("] ",_xlpm.raw)+2, 999), _xlpm.raw), IFERROR(TRIM(LEFT(_xlpm.s, FIND(" (",_xlpm.s)-1)), _xlpm.raw)) -> Fernando Mendoza | I2: =_xlfn.LET(_xlpm.raw, 'Other analyst '!G2, _xlpm.s, IF(LEFT(_xlpm.raw,1)="[", MID(_xlpm.raw, FIND("] ",_xlpm.raw)+2, 999), _xlpm.raw), IFERROR(TRIM(LEFT(_xlpm.s, FIND(" (",_xlpm.s)-1)), _xlpm.raw)) -> Fernando Mendoza | K2: =IF(OR(D2="", C2=""), 0, IF(OR(EXACT(TRIM(D2),TRIM(C2)), ISNUMBER(SEARCH(D2, C2)), ISNUMBER(SEARCH(C2, D2))), 1, 0)) -> 1 | L2: =IF(OR(E2="", C2=""), 0, IF(OR(EXACT(TRIM(E2),TRIM(C2)), ISNUMBER(SEARCH(E2, C2)), ISNUMBER(SEARCH(C2, E2))), 1, 0)) -> 1 | M2: =IF(OR(F2="", C2=""), 0, IF(OR(EXACT(TRIM(F2),TRIM(C2)), ISNUMBER(SEARCH(F2, C2)), ISNUMBER(SEARCH(C2, F2))), 1, 0)) -> 1 | N2: =IF(OR(G2="", C2=""), 0, IF(OR(EXACT(TRIM(G2),TRIM(C2)), ISNUMBER(SEARCH(G2, C2)), ISNUMBER(SEARCH(C2, G2))), 1, 0)) -> 1 | O2: =IF(OR(H2="", C2=""), 0, IF(OR(EXACT(TRIM(H2),TRIM(C2)), ISNUMBER(SEARCH(H2, C2)), ISNUMBER(SEARCH(C2, H2))), 1, 0)) -> 1 | P2: =IF(OR(I2="", C2=""), 0, IF(OR(EXACT(TRIM(I2),TRIM(C2)), ISNUMBER(SEARCH(I2, C2)), ISNUMBER(SEARCH(C2, I2))), 1, 0)) -> 1 | Q2: {=IF(D2="", 0, IF(SUMPRODUCT(--(ISNUMBER(SEARCH(D2, $C$2:$C$33)) + ISNUMBER(SEARCH($C$2:$C$33, D2))))>0, 1, 0))} -> 1 | R2: {=IF(E2="", 0, IF(SUMPRODUCT(--(ISNUMBER(SEARCH(E2, $C$2:$C$33)) + ISNUMBER(SEARCH($C$2:$C$33, E2))))>0, 1, 0))} -> 1 | S2: {=IF(F2="", 0, IF(SUMPRODUCT(--(ISNUMBER(SEARCH(F2, $C$2:$C$33)) + ISNUMBER(SEARCH($C$2:$C$33, F2))))>0, 1, 0))} -> 1 | T2: {=IF(G2="", 0, IF(SUMPRODUCT(--(ISNUMBER(SEARCH(G2, $C$2:$C$33)) + ISNUMBER(SEARCH($C$2:$C$33, G2))))>0, 1, 0))} -> 1 | U2: {=IF(H2="", 0, IF(SUMPRODUCT(--(ISNUMBER(SEARCH(H2, $C$2:$C$33)) + ISNUMBER(SEARCH($C$2:$C$33, H2))))>0, 1, 0))} -> 1 | V2: {=IF(I2="", 0, IF(SUMPRODUCT(--(ISNUMBER(SEARCH(I2, $C$2:$C$33)) + ISNUMBER(SEARCH($C$2:$C$33, I2))))>0, 1, 0))} -> 1 | W2: {=IF(D2="",0,IF(SUMPRODUCT((ISNUMBER(SEARCH(D2,$C$2:$C$33))+ISNUMBER(SEARCH($C$2:$C$33,D2)))*($B$2:$B$33=$B2))>0,1,0))} -> 1 | X2: {=IF(E2="",0,IF(SUMPRODUCT((ISNUMBER(SEARCH(E2,$C$2:$C$33))+ISNUMBER(SEARCH($C$2:$C$33,E2)))*($B$2:$B$33=$B2))>0,1,0))} -> 1 | Y2: {=IF(F2="",0,IF(SUMPRODUCT((ISNUMBER(SEARCH(F2,$C$2:$C$33))+ISNUMBER(SEARCH($C$2:$C$33,F2)))*($B$2:$B$33=$B2))>0,1,0))} -> 1 | Z2: {=IF(G2="",0,IF(SUMPRODUCT((ISNUMBER(SEARCH(G2,$C$2:$C$33))+ISNUMBER(SEARCH($C$2:$C$33,G2)))*($B$2:$B$33=$B2))>0,1,0))} -> 1 | AA2: {=IF(H2="",0,IF(SUMPRODUCT((ISNUMBER(SEARCH(H2,$C$2:$C$33))+ISNUMBER(SEARCH($C$2:$C$33,H2)))*($B$2:$B$33=$B2))>0,1,0))} -> 1 | AB2: {=IF(I2="",0,IF(SUMPRODUCT((ISNUMBER(SEARCH(I2,$C$2:$C$33))+ISNUMBER(SEARCH($C$2:$C$33,I2)))*($B$2:$B$33=$B2))>0,1,0))} -> 1 | AC2: Fernando Mendoza | AD2: Fernando Mendoza | AE2: Fernando Mendoza | AF2: =IF(AC2="",0,IF((ISNUMBER(SEARCH(AC2,C2))+ISNUMBER(SEARCH(C2,AC2)))>0,1,0)) -> 1 | AG2: {=IF(AC2="",0,IF(SUMPRODUCT((ISNUMBER(SEARCH(AC2,$C$2:$C$33))+ISNUMBER(SEARCH($C$2:$C$33,AC2))))>0,1,0))} -> 1 | AH2: {=IF(AC2="",0,IF(SUMPRODUCT((ISNUMBER(SEARCH(AC2,$C$2:$C$33))+ISNUMBER(SEARCH($C$2:$C$33,AC2)))*($B$2:$B$33=$B2))>0,1,0))} -> 1 | AI2: =IF(AD2="",0,IF((ISNUMBER(SEARCH(AD2,C2))+ISNUMBER(SEARCH(C2,AD2)))>0,1,0)) -> 1 | AJ2: {=IF(AD2="",0,IF(SUMPRODUCT((ISNUMBER(SEARCH(AD2,$C$2:$C$33))+ISNUMBER(SEARCH($C$2:$C$33,AD2))))>0,1,0))} -> 1 | AK2: {=IF(AD2="",0,IF(SUMPRODUCT((ISNUMBER(SEARCH(AD2,$C$2:$C$33))+ISNUMBER(SEARCH($C$2:$C$33,AD2)))*($B$2:$B$33=$B2))>0,1,0))} -> 1 | AL2: =IF(AE2="",0,IF((ISNUMBER(SEARCH(AE2,C2))+ISNUMBER(SEARCH(C2,AE2)))>0,1,0)) -> 1 | AM2: {=IF(AE2="",0,IF(SUMPRODUCT((ISNUMBER(SEARCH(AE2,$C$2:$C$33))+ISNUMBER(SEARCH($C$2:$C$33,AE2))))>0,1,0))} -> 1 | AN2: {=IF(AE2="",0,IF(SUMPRODUCT((ISNUMBER(SEARCH(AE2,$C$2:$C$33))+ISNUMBER(SEARCH($C$2:$C$33,AE2)))*($B$2:$B$33=$B2))>0,1,0))} -> 1 | AO2: {=_xlfn.LET(_xlpm.raw,'Other analyst '!K2,_xlpm.mockNames,'Colin''s Mock'!$D$2:$D$258,_xlpm.analystNames,_xlfn.TOCOL($E$2:$I$33),_xlpm.newNames,_xlfn.TOCOL('Other analyst '!$K$2:$R$33),_xlpm.allNames,_xlfn.VSTACK(_xlpm.mockNames,_xlpm.analystNames,_xlpm.newNames),_xlpm.matches,_xlfn._xlws.FILTER(_xlpm.allNames,ISNUMBER(SEARCH(_xlpm.allNames,_xlpm.raw))*(LEN(_xlpm.allNames)>3),""),IF(ISERROR(INDEX(_xlpm.matches,1)),_xlpm.raw,INDEX(_xlpm.matches,1)))} -> Fernando Mendoza | AP2: =IF(OR(AO2="",AO2=0),0,IF(OR(ISNUMBER(SEARCH(AO2,$C2)),ISNUMBER(SEARCH($C2,AO2))),1,0)) -> 1 | AQ2: {=IF(OR(AO2="",AO2=0),0,IF(SUMPRODUCT(--(ISNUMBER(SEARCH(AO2,$C$2:$C$33))+ISNUMBER(SEARCH($C$2:$C$33,AO2))))>0,1,0))} -> 1 | AR2: {=IF(OR(AO2="",AO2=0),0,IF(SUMPRODUCT((ISNUMBER(SEARCH(AO2,$C$2:$C$33))+ISNUMBER(SEARCH($C$2:$C$33,AO2)))*($B$2:$B$33=$B2))>0,1,0))} -> 1 | AS2: {=_xlfn.LET(_xlpm.raw,'Other analyst '!L2,_xlpm.mockNames,'Colin''s Mock'!$D$2:$D$258,_xlpm.analystNames,_xlfn.TOCOL($E$2:$I$33),_xlpm.newNames,_xlfn.TOCOL('Other analyst '!$K$2:$R$33),_xlpm.allNames,_xlfn.VSTACK(_xlpm.mockNames,_xlpm.analystNames,_xlpm.newNames),_xlpm.matches,_xlfn._xlws.FILTER(_xlpm.allNames,ISNUMBER(SEARCH(_xlpm.allNames,_xlpm.raw))*(LEN(_xlpm.allNames)>3),""),IF(ISERROR(INDEX(_xlpm.matches,1)),_xlpm.raw,INDEX(_xlpm.matches,1)))} -> Fernando Mendoza | AT2: =IF(OR(AS2="",AS2=0),0,IF(OR(ISNUMBER(SEARCH(AS2,$C2)),ISNUMBER(SEARCH($C2,AS2))),1,0)) -> 1 | AU2: {=IF(OR(AS2="",AS2=0),0,IF(SUMPRODUCT(--(ISNUMBER(SEARCH(AS2,$C$2:$C$33))+ISNUMBER(SEARCH($C$2:$C$33,AS2))))>0,1,0))} -> 1 | AV2: {=IF(OR(AS2="",AS2=0),0,IF(SUMPRODUCT((ISNUMBER(SEARCH(AS2,$C$2:$C$33))+ISNUMBER(SEARCH($C$2:$C$33,AS2)))*($B$2:$B$33=$B2))>0,1,0))} -> 1 | AW2: {=_xlfn.LET(_xlpm.raw,'Other analyst '!M2,_xlpm.mockNames,'Colin''s Mock'!$D$2:$D$258,_xlpm.analystNames,_xlfn.TOCOL($E$2:$I$33),_xlpm.newNames,_xlfn.TOCOL('Other analyst '!$K$2:$R$33),_xlpm.allNames,_xlfn.VSTACK(_xlpm.mockNames,_xlpm.analystNames,_xlpm.newNames),_xlpm.matches,_xlfn._xlws.FILTER(_xlpm.allNames,ISNUMBER(SEARCH(_xlpm.allNames,_xlpm.raw))*(LEN(_xlpm.allNames)>3),""),IF(ISERROR(INDEX(_xlpm.matches,1)),_xlpm.raw,INDEX(_xlpm.matches,1)))} -> Fernando Mendoza | AX2: =IF(OR(AW2="",AW2=0),0,IF(OR(ISNUMBER(SEARCH(AW2,$C2)),ISNUMBER(SEARCH($C2,AW2))),1,0)) -> 1 | AY2: {=IF(OR(AW2="",AW2=0),0,IF(SUMPRODUCT(--(ISNUMBER(SEARCH(AW2,$C$2:$C$33))+ISNUMBER(SEARCH($C$2:$C$33,AW2))))>0,1,0))} -> 1 | AZ2: {=IF(OR(AW2="",AW2=0),0,IF(SUMPRODUCT((ISNUMBER(SEARCH(AW2,$C$2:$C$33))+ISNUMBER(SEARCH($C$2:$C$33,AW2)))*($B$2:$B$33=$B2))>0,1,0))} -> 1 | BA2: {=_xlfn.LET(_xlpm.raw,'Other analyst '!N2,_xlpm.mockNames,'Colin''s Mock'!$D$2:$D$258,_xlpm.analystNames,_xlfn.TOCOL($E$2:$I$33),_xlpm.newNames,_xlfn.TOCOL('Other analyst '!$K$2:$R$33),_xlpm.allNames,_xlfn.VSTACK(_xlpm.mockNames,_xlpm.analystNames,_xlpm.newNames),_xlpm.matches,_xlfn._xlws.FILTER(_xlpm.allNames,ISNUMBER(SEARCH(_xlpm.allNames,_xlpm.raw))*(LEN(_xlpm.allNames)>3),""),IF(ISERROR(INDEX(_xlpm.matches,1)),_xlpm.raw,INDEX(_xlpm.matches,1)))} -> Fernando Mendoza | BB2: =IF(OR(BA2="",BA2=0),0,IF(OR(ISNUMBER(SEARCH(BA2,$C2)),ISNUMBER(SEARCH($C2,BA2))),1,0)) -> 1 | BC2: {=IF(OR(BA2="",BA2=0),0,IF(SUMPRODUCT(--(ISNUMBER(SEARCH(BA2,$C$2:$C$33))+ISNUMBER(SEARCH($C$2:$C$33,BA2))))>0,1,0))} -> 1 | BD2: {=IF(OR(BA2="",BA2=0),0,IF(SUMPRODUCT((ISNUMBER(SEARCH(BA2,$C$2:$C$33))+ISNUMBER(SEARCH($C$2:$C$33,BA2)))*($B$2:$B$33=$B2))>0,1,0))} -> 1 | BE2: {=_xlfn.LET(_xlpm.raw,'Other analyst '!O2,_xlpm.mockNames,'Colin''s Mock'!$D$2:$D$258,_xlpm.analystNames,_xlfn.TOCOL($E$2:$I$33),_xlpm.newNames,_xlfn.TOCOL('Other analyst '!$K$2:$R$33),_xlpm.allNames,_xlfn.VSTACK(_xlpm.mockNames,_xlpm.analystNames,_xlpm.newNames),_xlpm.matches,_xlfn._xlws.FILTER(_xlpm.allNames,ISNUMBER(SEARCH(_xlpm.allNames,_xlpm.raw))*(LEN(_xlpm.allNames)>3),""),IF(ISERROR(INDEX(_xlpm.matches,1)),_xlpm.raw,INDEX(_xlpm.matches,1)))} -> Fernando Mendoza | BF2: =IF(OR(BE2="",BE2=0),0,IF(OR(ISNUMBER(SEARCH(BE2,$C2)),ISNUMBER(SEARCH($C2,BE2))),1,0)) -> 1 | BG2: {=IF(OR(BE2="",BE2=0),0,IF(SUMPRODUCT(--(ISNUMBER(SEARCH(BE2,$C$2:$C$33))+ISNUMBER(SEARCH($C$2:$C$33,BE2))))>0,1,0))} -> 1 | BH2: {=IF(OR(BE2="",BE2=0),0,IF(SUMPRODUCT((ISNUMBER(SEARCH(BE2,$C$2:$C$33))+ISNUMBER(SEARCH($C$2:$C$33,BE2)))*($B$2:$B$33=$B2))>0,1,0))} -> 1 | BI2: {=_xlfn.LET(_xlpm.raw,'Other analyst '!P2,_xlpm.mockNames,'Colin''s Mock'!$D$2:$D$258,_xlpm.analystNames,_xlfn.TOCOL($E$2:$I$33),_xlpm.newNames,_xlfn.TOCOL('Other analyst '!$K$2:$R$33),_xlpm.allNames,_xlfn.VSTACK(_xlpm.mockNames,_xlpm.analystNames,_xlpm.newNames),_xlpm.matches,_xlfn._xlws.FILTER(_xlpm.allNames,ISNUMBER(SEARCH(_xlpm.allNames,_xlpm.raw))*(LEN(_xlpm.allNames)>3),""),IF(ISERROR(INDEX(_xlpm.matches,1)),_xlpm.raw,INDEX(_xlpm.matches,1)))} -> Fernando Mendoza | BJ2: =IF(OR(BI2="",BI2=0),0,IF(OR(ISNUMBER(SEARCH(BI2,$C2)),ISNUMBER(SEARCH($C2,BI2))),1,0)) -> 1 | BK2: {=IF(OR(BI2="",BI2=0),0,IF(SUMPRODUCT(--(ISNUMBER(SEARCH(BI2,$C$2:$C$33))+ISNUMBER(SEARCH($C$2:$C$33,BI2))))>0,1,0))} -> 1 | BL2: {=IF(OR(BI2="",BI2=0),0,IF(SUMPRODUCT((ISNUMBER(SEARCH(BI2,$C$2:$C$33))+ISNUMBER(SEARCH($C$2:$C$33,BI2)))*($B$2:$B$33=$B2))>0,1,0))} -> 1 | BM2: {=_xlfn.LET(_xlpm.raw,'Other analyst '!Q2,_xlpm.mockNames,'Colin''s Mock'!$D$2:$D$258,_xlpm.analystNames,_xlfn.TOCOL($E$2:$I$33),_xlpm.newNames,_xlfn.TOCOL('Other analyst '!$K$2:$R$33),_xlpm.allNames,_xlfn.VSTACK(_xlpm.mockNames,_xlpm.analystNames,_xlpm.newNames),_xlpm.matches,_xlfn._xlws.FILTER(_xlpm.allNames,ISNUMBER(SEARCH(_xlpm.allNames,_xlpm.raw))*(LEN(_xlpm.allNames)>3),""),IF(ISERROR(INDEX(_xlpm.matches,1)),_xlpm.raw,INDEX(_xlpm.matches,1)))} -> Fernando Mendoza | BN2: =IF(OR(BM2="",BM2=0),0,IF(OR(ISNUMBER(SEARCH(BM2,$C2)),ISNUMBER(SEARCH($C2,BM2))),1,0)) -> 1 | BO2: {=IF(OR(BM2="",BM2=0),0,IF(SUMPRODUCT(--(ISNUMBER(SEARCH(BM2,$C$2:$C$33))+ISNUMBER(SEARCH($C$2:$C$33,BM2))))>0,1,0))} -> 1 | BP2: {=IF(OR(BM2="",BM2=0),0,IF(SUMPRODUCT((ISNUMBER(SEARCH(BM2,$C$2:$C$33))+ISNUMBER(SEARCH($C$2:$C$33,BM2)))*($B$2:$B$33=$B2))>0,1,0))} -> 1 | BQ2: {=_xlfn.LET(_xlpm.raw,'Other analyst '!R2,_xlpm.mockNames,'Colin''s Mock'!$D$2:$D$258,_xlpm.analystNames,_xlfn.TOCOL($E$2:$I$33),_xlpm.newNames,_xlfn.TOCOL('Other analyst '!$K$2:$R$33),_xlpm.allNames,_xlfn.VSTACK(_xlpm.mockNames,_xlpm.analystNames,_xlpm.newNames),_xlpm.matches,_xlfn._xlws.FILTER(_xlpm.allNames,ISNUMBER(SEARCH(_xlpm.allNames,_xlpm.raw))*(LEN(_xlpm.allNames)>3),""),IF(ISERROR(INDEX(_xlpm.matches,1)),_xlpm.raw,INDEX(_xlpm.matches,1)))} -> Fernando Mendoza | BR2: =IF(OR(BQ2="",BQ2=0),0,IF(OR(ISNUMBER(SEARCH(BQ2,$C2)),ISNUMBER(SEARCH($C2,BQ2))),1,0)) -> 1 | BS2: {=IF(OR(BQ2="",BQ2=0),0,IF(SUMPRODUCT(--(ISNUMBER(SEARCH(BQ2,$C$2:$C$33))+ISNUMBER(SEARCH($C$2:$C$33,BQ2))))>0,1,0))} -> 1 | BT2: {=IF(OR(BQ2="",BQ2=0),0,IF(SUMPRODUCT((ISNUMBER(SEARCH(BQ2,$C$2:$C$33))+ISNUMBER(SEARCH($C$2:$C$33,BQ2)))*($B$2:$B$33=$B2))>0,1,0))} -> 1 | BU2: ='Colin Mock wTrade'!D2 -> Fernando Mendoza | BV2: =IF(BU2="",0,IF(OR(ISNUMBER(SEARCH(BU2,C2)),ISNUMBER(SEARCH(C2,BU2))),1,0)) -> 1 | BW2: {=IF(BU2="",0,IF(SUMPRODUCT(--(ISNUMBER(SEARCH(BU2,$C$2:$C$33))+ISNUMBER(SEARCH($C$2:$C$33,BU2))))>0,1,0))} -> 1 | BX2: {=IF(BU2="",0,IFERROR(IF(SUMPRODUCT((ISNUMBER(SEARCH(BU2,$C$2:$C$33))+ISNUMBER(SEARCH($C$2:$C$33,BU2)))*($B$2:$B$33=VLOOKUP('Colin Mock wTrade'!C2,$CA$1:$CB$32,2,FALSE)))>0,1,0),0))} -> 1 | CA2: NYJ | CB2: Jets | CC2: ='Other analyst '!S2 -> Fernando Mendoza | CD2: =IF(CC2="",0,IF(OR(ISNUMBER(SEARCH(CC2,C2)),ISNUMBER(SEARCH(C2,CC2))),1,0)) -> 1 | CE2: {=IF(CC2="",0,IF(SUMPRODUCT(--(ISNUMBER(SEARCH(CC2,$C$2:$C$33))+ISNUMBER(SEARCH($C$2:$C$33,CC2))))>0,1,0))} -> 1 | CF2: {=IF(CC2="",0,IF(SUMPRODUCT((ISNUMBER(SEARCH(CC2,$C$2:$C$33))+ISNUMBER(SEARCH($C$2:$C$33,CC2)))*($B$2:$B$33=$B2))>0,1,0))} -> 1 | CG2: ='Other analyst '!T2 -> Fernando Mendoza | CH2: =IF(CG2="",0,IF(OR(ISNUMBER(SEARCH(CG2,C2)),ISNUMBER(SEARCH(C2,CG2))),1,0)) -> 1 | CI2: {=IF(CG2="",0,IF(SUMPRODUCT(--(ISNUMBER(SEARCH(CG2,$C$2:$C$33))+ISNUMBER(SEARCH($C$2:$C$33,CG2))))>0,1,0))} -> 1 | CJ2: {=IF(CG2="",0,IF(SUMPRODUCT((ISNUMBER(SEARCH(CG2,$C$2:$C$33))+ISNUMBER(SEARCH($C$2:$C$33,CG2)))*($B$2:$B$33=$B2))>0,1,0))} -> 1 | CK2: ='Other analyst '!U2 -> Fernando Mendoza | CL2: =IF(CK2="",0,IF(OR(ISNUMBER(SEARCH(CK2,C2)),ISNUMBER(SEARCH(C2,CK2))),1,0)) -> 1 | CM2: {=IF(CK2="",0,IF(SUMPRODUCT(--(ISNUMBER(SEARCH(CK2,$C$2:$C$33))+ISNUMBER(SEARCH($C$2:$C$33,CK2))))>0,1,0))} -> 1 | CN2: {=IF(CK2="",0,IF(SUMPRODUCT((ISNUMBER(SEARCH(CK2,$C$2:$C$33))+ISNUMBER(SEARCH($C$2:$C$33,CK2)))*($B$2:$B$33=$B2))>0,1,0))} -> 1 | CO2: ='Other analyst '!V2 -> Arch Manning | CP2: =IF(CO2="",0,IF(OR(ISNUMBER(SEARCH(CO2,C2)),ISNUMBER(SEARCH(C2,CO2))),1,0)) -> 0 | CQ2: {=IF(CO2="",0,IF(SUMPRODUCT(--(ISNUMBER(SEARCH(CO2,$C$2:$C$33))+ISNUMBER(SEARCH($C$2:$C$33,CO2))))>0,1,0))} -> 0 | CR2: {=IF(CO2="",0,IF(SUMPRODUCT((ISNUMBER(SEARCH(CO2,$C$2:$C$33))+ISNUMBER(SEARCH($C$2:$C$33,CO2)))*($B$2:$B$33=$B2))>0,1,0))} -> 0 | CS2: ='Other analyst '!W2 -> Fernando Mendoza | CT2: =IF(CS2="",0,IF(OR(ISNUMBER(SEARCH(CS2,C2)),ISNUMBER(SEARCH(C2,CS2))),1,0)) -> 1 | CU2: {=IF(CS2="",0,IF(SUMPRODUCT(--(ISNUMBER(SEARCH(CS2,$C$2:$C$33))+ISNUMBER(SEARCH($C$2:$C$33,CS2))))>0,1,0))} -> 1 | CV2: {=IF(CS2="",0,IFERROR(IF(SUMPRODUCT((ISNUMBER(SEARCH(CS2,$C$2:$C$33))+ISNUMBER(SEARCH($C$2:$C$33,CS2)))*(ISNUMBER(SEARCH($B$2:$B$33,'Other analyst '!B2))+ISNUMBER(SEARCH('Other analyst '!B2,$B$2:$B$33))))>0,1,0),0))} -> 1 | CW2: ='Other analyst '!AD2 -> Fernando Mendoza | CX2: =IF(CW2="",0,IF(OR(ISNUMBER(SEARCH(CW2,C2)),ISNUMBER(SEARCH(C2,CW2))),1,0)) -> 1 | CY2: {=IF(CW2="",0,IF(SUMPRODUCT(--(ISNUMBER(SEARCH(CW2,$C$2:$C$33))+ISNUMBER(SEARCH($C$2:$C$33,CW2))))>0,1,0))} -> 1 | CZ2: {=IF(CW2="",0,IF(SUMPRODUCT((ISNUMBER(SEARCH(CW2,$C$2:$C$33))+ISNUMBER(SEARCH($C$2:$C$33,CW2)))*($B$2:$B$33=$B2))>0,1,0))} -> 1 | DA2: ='Other analyst '!AE2 -> Fernando Mendoza | DB2: =IF(DA2="",0,IF(OR(ISNUMBER(SEARCH(DA2,C2)),ISNUMBER(SEARCH(C2,DA2))),1,0)) -> 1 | DC2: {=IF(DA2="",0,IF(SUMPRODUCT(--(ISNUMBER(SEARCH(DA2,$C$2:$C$33))+ISNUMBER(SEARCH($C$2:$C$33,DA2))))>0,1,0))} -> 1 | DD2: {=IF(DA2="",0,IF(SUMPRODUCT((ISNUMBER(SEARCH(DA2,$C$2:$C$33))+ISNUMBER(SEARCH($C$2:$C$33,DA2)))*($B$2:$B$33=$B2))>0,1,0))} -> 1 | DE2: ='Other analyst '!AF2 -> Fernando Mendoza | DF2: =IF(DE2="",0,IF(OR(ISNUMBER(SEARCH(DE2,C2)),ISNUMBER(SEARCH(C2,DE2))),1,0)) -> 1 | DG2: {=IF(DE2="",0,IF(SUMPRODUCT(--(ISNUMBER(SEARCH(DE2,$C$2:$C$33))+ISNUMBER(SEARCH($C$2:$C$33,DE2))))>0,1,0))} -> 1 | DH2: {=IF(DE2="",0,IF(SUMPRODUCT((ISNUMBER(SEARCH(DE2,$C$2:$C$33))+ISNUMBER(SEARCH($C$2:$C$33,DE2)))*($B$2:$B$33=$B2))>0,1,0))} -> 1 | DI2: ='Other analyst '!AG2 -> Fernando Mendoza | DJ2: =IF(DI2="",0,IF(OR(ISNUMBER(SEARCH(DI2,C2)),ISNUMBER(SEARCH(C2,DI2))),1,0)) -> 1 | DK2: {=IF(DI2="",0,IF(SUMPRODUCT(--(ISNUMBER(SEARCH(DI2,$C$2:$C$33))+ISNUMBER(SEARCH($C$2:$C$33,DI2))))>0,1,0))} -> 1 | DL2: {=IF(DI2="",0,IF(SUMPRODUCT((ISNUMBER(SEARCH(DI2,$C$2:$C$33))+ISNUMBER(SEARCH($C$2:$C$33,DI2)))*($B$2:$B$33=$B2))>0,1,0))} -> 1 | DM2: ='Other analyst '!AB2 -> Fernando Mendoza | DN2: =IF(DM2="",0,IF(OR(ISNUMBER(SEARCH(DM2,C2)),ISNUMBER(SEARCH(C2,DM2))),1,0)) -> 1 | DO2: {=IF(DM2="",0,IF(SUMPRODUCT(--(ISNUMBER(SEARCH(DM2,$C$2:$C$33))+ISNUMBER(SEARCH($C$2:$C$33,DM2))))>0,1,0))} -> 1 | DP2: {=IF(DM2="",0,IFERROR(IF(SUMPRODUCT((ISNUMBER(SEARCH(DM2,$C$2:$C$33))+ISNUMBER(SEARCH($C$2:$C$33,DM2)))*(ISNUMBER(SEARCH($B$2:$B$33,'Other analyst '!B2))+ISNUMBER(SEARCH('Other analyst '!B2,$B$2:$B$33))))>0,1,0),0))} -> 1 | DQ2: ='Other analyst '!AC2 -> Fernando Mendoza | DR2: =IF(DQ2="",0,IF(OR(ISNUMBER(SEARCH(DQ2,C2)),ISNUMBER(SEARCH(C2,DQ2))),1,0)) -> 1 | DS2: {=IF(DQ2="",0,IF(SUMPRODUCT(--(ISNUMBER(SEARCH(DQ2,$C$2:$C$33))+ISNUMBER(SEARCH($C$2:$C$33,DQ2))))>0,1,0))} -> 1 | DT2: {=IF(DQ2="",0,IFERROR(IF(SUMPRODUCT((ISNUMBER(SEARCH(DQ2,$C$2:$C$33))+ISNUMBER(SEARCH($C$2:$C$33,DQ2)))*(ISNUMBER(SEARCH($B$2:$B$33,'Other analyst '!B2))+ISNUMBER(SEARCH('Other analyst '!B2,$B$2:$B$33))))>0,1,0),0))} -> 1 | DU2: =IFERROR(TRIM(LEFT(IF(ISNUMBER(SEARCH("]",'Other analyst '!X2)),MID('Other analyst '!X2,SEARCH("]",'Other analyst '!X2)+1,200),'Other analyst '!X2),IFERROR(SEARCH(" (",IF(ISNUMBER(SEARCH("]",'Other analyst '!X2)),MID('Other analyst '!X2,SEARCH("]",'Other analyst '!X2)+1,200),'Other analyst '!X2))-1,LEN('Other analyst '!X2)))),"") -> Fernando Mendoza | DV2: =IF(DU2="",0,IF(OR(ISNUMBER(SEARCH(DU2,C2)),ISNUMBER(SEARCH(C2,DU2))),1,0)) -> 1 | DW2: {=IF(DU2="",0,IF(SUMPRODUCT((ISNUMBER(SEARCH(DU2,$C$2:$C$33))+ISNUMBER(SEARCH($C$2:$C$33,DU2))))>0,1,0))} -> 1 | DX2: 0 | DY2: =IFERROR(TRIM(LEFT(IF(ISNUMBER(SEARCH("]",'Other analyst '!Y2)),MID('Other analyst '!Y2,SEARCH("]",'Other analyst '!Y2)+1,200),'Other analyst '!Y2),IFERROR(SEARCH(" (",IF(ISNUMBER(SEARCH("]",'Other analyst '!Y2)),MID('Other analyst '!Y2,SEARCH("]",'Other analyst '!Y2)+1,200),'Other analyst '!Y2))-1,LEN('Other analyst '!Y2)))),"") -> Fernando Mendoza | DZ2: =IF(DY2="",0,IF(OR(ISNUMBER(SEARCH(DY2,C2)),ISNUMBER(SEARCH(C2,DY2))),1,0)) -> 1 | EA2: {=IF(DY2="",0,IF(SUMPRODUCT((ISNUMBER(SEARCH(DY2,$C$2:$C$33))+ISNUMBER(SEARCH($C$2:$C$33,DY2))))>0,1,0))} -> 1 | EB2: 0 | EC2: =IFERROR(TRIM(LEFT(IF(ISNUMBER(SEARCH("]",'Other analyst '!Z2)),MID('Other analyst '!Z2,SEARCH("]",'Other analyst '!Z2)+1,200),'Other analyst '!Z2),IFERROR(SEARCH(" (",IF(ISNUMBER(SEARCH("]",'Other analyst '!Z2)),MID('Other analyst '!Z2,SEARCH("]",'Other analyst '!Z2)+1,200),'Other analyst '!Z2))-1,LEN('Other analyst '!Z2)))),"") -> Fernando Mendoza | ED2: =IF(EC2="",0,IF(OR(ISNUMBER(SEARCH(EC2,C2)),ISNUMBER(SEARCH(C2,EC2))),1,0)) -> 1 | EE2: {=IF(EC2="",0,IF(SUMPRODUCT((ISNUMBER(SEARCH(EC2,$C$2:$C$33))+ISNUMBER(SEARCH($C$2:$C$33,EC2))))>0,1,0))} -> 1 | EF2: 0 | EG2: =IFERROR(TRIM(LEFT(IF(ISNUMBER(SEARCH("]",'Other analyst '!AA2)),MID('Other analyst '!AA2,SEARCH("]",'Other analyst '!AA2)+1,200),'Other analyst '!AA2),IFERROR(SEARCH(" (",IF(ISNUMBER(SEARCH("]",'Other analyst '!AA2)),MID('Other analyst '!AA2,SEARCH("]",'Other analyst '!AA2)+1,200),'Other analyst '!AA2))-1,LEN('Other analyst '!AA2)))),"") -> Fernando Mendoza | EH2: =IF(EG2="",0,IF(OR(ISNUMBER(SEARCH(EG2,C2)),ISNUMBER(SEARCH(C2,EG2))),1,0)) -> 1 | EI2: {=IF(EG2="",0,IF(SUMPRODUCT((ISNUMBER(SEARCH(EG2,$C$2:$C$33))+ISNUMBER(SEARCH($C$2:$C$33,EG2))))>0,1,0))} -> 1 | EJ2: 0 | EK2: =K2+L2+M2+N2+O2+P2+AF2+AI2+AL2+AP2+AT2+AX2+BB2+BF2+BJ2+BN2+BR2+BV2+CD2+CH2+CL2+CP2+CT2+DV2+DZ2+ED2+EH2+DN2+DR2+CX2+DB2+DF2+DJ2 -> 32
